Traceback (most recent call last):
  File "/home/raid/miniconda3/envs/l2p/lib/python3.10/site-packages/torch/__init__.py", line 178, in _load_global_deps
    ctypes.CDLL(lib_path, mode=ctypes.RTLD_GLOBAL)
  File "/home/raid/miniconda3/envs/l2p/lib/python3.10/ctypes/__init__.py", line 374, in __init__
    self._handle = _dlopen(self._name, mode)
OSError: libcudart.so.12: cannot open shared object file: No such file or directory

During handling of the above exception, another exception occurred:

Traceback (most recent call last):
  File "/home/raid/miniconda3/envs/l2p/lib/python3.10/runpy.py", line 187, in _run_module_as_main
    mod_name, mod_spec, code = _get_module_details(mod_name, _Error)
  File "/home/raid/miniconda3/envs/l2p/lib/python3.10/runpy.py", line 110, in _get_module_details
    __import__(pkg_name)
  File "/home/raid/miniconda3/envs/l2p/lib/python3.10/site-packages/torch/__init__.py", line 238, in <module>
    _load_global_deps()
  File "/home/raid/miniconda3/envs/l2p/lib/python3.10/site-packages/torch/__init__.py", line 200, in _load_global_deps
    ctypes.CDLL(lib_path, mode=ctypes.RTLD_GLOBAL)
  File "/home/raid/miniconda3/envs/l2p/lib/python3.10/ctypes/__init__.py", line 374, in __init__
    self._handle = _dlopen(self._name, mode)
OSError: libcudart.so.12: cannot open shared object file: No such file or directory
Traceback (most recent call last):
  File "/home/raid/miniconda3/envs/l2p/lib/python3.10/site-packages/torch/__init__.py", line 178, in _load_global_deps
    ctypes.CDLL(lib_path, mode=ctypes.RTLD_GLOBAL)
  File "/home/raid/miniconda3/envs/l2p/lib/python3.10/ctypes/__init__.py", line 374, in __init__
    self._handle = _dlopen(self._name, mode)
OSError: libcudart.so.12: cannot open shared object file: No such file or directory

During handling of the above exception, another exception occurred:

Traceback (most recent call last):
  File "/home/raid/miniconda3/envs/l2p/lib/python3.10/runpy.py", line 187, in _run_module_as_main
    mod_name, mod_spec, code = _get_module_details(mod_name, _Error)
  File "/home/raid/miniconda3/envs/l2p/lib/python3.10/runpy.py", line 110, in _get_module_details
    __import__(pkg_name)
  File "/home/raid/miniconda3/envs/l2p/lib/python3.10/site-packages/torch/__init__.py", line 238, in <module>
    _load_global_deps()
  File "/home/raid/miniconda3/envs/l2p/lib/python3.10/site-packages/torch/__init__.py", line 200, in _load_global_deps
    ctypes.CDLL(lib_path, mode=ctypes.RTLD_GLOBAL)
  File "/home/raid/miniconda3/envs/l2p/lib/python3.10/ctypes/__init__.py", line 374, in __init__
    self._handle = _dlopen(self._name, mode)
OSError: libcudart.so.12: cannot open shared object file: No such file or directory
